<?xml version="1.0"?>

<robot name="ir100_robot" xmlns:xacro="http://ros.org/wiki/xacro">
<xacro:macro name="ir100_robot">
  <material name="OffWhite">
    <color rgba="0.8 0.8 0.8 1.0"/>
  </material>
  <material name="black">
    <color rgba="0.8 0.8 0.8 1.0"/>
  </material>
  <link name="base_link" >
    <inertial>
      <mass value="0.0001" rpy="0 0 0" />
      <origin xyz="0 0 0" />
      <inertia ixx="0.0001" ixy="0.0" ixz="0.0"
               iyy="0.0001" iyz="0.0"
               izz="0.0001" />
    </inertial>
    <visual>
      <origin xyz="0 0 0" rpy="0 0 0" />
      <geometry>
        <mesh filename="package://ir100_description/meshes/base_link.stl" />
      </geometry>
      <material name="OffWhite" />
    </visual>
    <collision>
      <origin xyz="0 0 0.15" rpy="0 0 0" />
      <geometry>
       <box size="0.8 0.6 0.4" />
      </geometry>
    </collision>
  </link>


<link name="top_link" >
 <visual>
            <geometry>
            <mesh filename="package://ir100_description/meshes/top.STL" />
            </geometry>
            <origin xyz="0 0 0" rpy="0 0 0" />
            <material name="black">
                <color rgba="0.7 0.5 0 0.5" />
            </material>
        </visual>
 <collision>
      <geometry>
      <box size="0.25 0.5 1" />
      </geometry>
      <origin xyz="-0.2 0 0.51" rpy="0 0 0" />

    </collision>
    <collision>
      <geometry>
      <box size="0.18 0.35 0.2" />
      </geometry>
      <origin xyz="0.02 0 0.11" rpy="0 0 0" />

    </collision>
 </link>       
<joint name="top_joint" type="fixed">
    <origin xyz="0 0 0.32" rpy="0 0 0" />
    <parent link="base_link" />
    <child link="top_link" />
  </joint>
<link name="hand_link" >
    <visual>
      <origin xyz="0 0 0" rpy="0 0 0" />
      <geometry>
        <mesh filename="package://ir100_description/meshes/Hard.STL" />
      </geometry>
      <material name="black">
        <color rgba="0.7 0.5 0 0.5" />
      </material>
    </visual>
    <collision>
      <origin xyz="0 0 0" rpy="0 0 0" />
      <geometry>
       <mesh filename="package://ir100_description/meshes/Hard.STL" />
      </geometry>
    </collision>
</link>
<joint name="hand_joint" type="prismatic">
    <origin xyz="-0.08 0 0.7" rpy="0 0 0" />
    <parent link="base_link" />
    <child link="hand_link" />
    <axis xyz="0 0 1" />
 <limit effort="30" velocity="1.0" lower="0" upper="0.4" />
  </joint>
  <link name="left_wheel_link" >
  </link>
  <joint name="left_wheel_joint" type="continuous">
    <origin xyz="0 0.25 0.03" rpy="0 0 0" />
    <parent link="base_link" />
    <child link="left_wheel_link" />
    <axis xyz="0 1 0" />
  </joint>
<link name="left_arm_link" >
</link>
<joint name="left_arm_joint" type="fixed">
    <origin xyz="0.084 0.2 0.038" rpy="-2.3562 0 0" /> 
    <parent link="hand_link" />
    <child link="left_arm_link" />
</joint>
<link name="right_arm_link" >
</link>
<joint name="right_arm_joint" type="fixed">
    <origin xyz="0.084 -0.2 0.038" rpy="2.3562 0 0" /> 
    <parent link="hand_link" />
    <child link="right_arm_link" />
</joint>

  <link name="right_wheel_link" >
  </link>
  <joint name="right_wheel_joint" type="continuous">
    <origin xyz="0 -0.25 0.03" rpy="3.14159265358979 3.14159265358979 3.14159265358979" />
    <parent link="base_link" />
    <child link="right_wheel_link" />
    <axis xyz="0 1 0" />
  </joint>


  <link name="imu_link" >
  </link>
  <joint name="imu_joint" type="fixed">
    <origin xyz="0 0 0" rpy="0 0 0" />
    <parent link="base_link" />
    <child link="imu_link" />
  </joint>


  <!-- <link name="camera_link" >

  </link>

  <joint name="camera_joint" type="fixed">

    <origin xyz="0.4 0 0.365" rpy="0 0 0" />

    <parent link="base_link" />

    <child link="camera_link" />

  </joint> -->

  <link name="laser" >
  </link>
  <joint name="laser_joint" type="fixed">
    <origin xyz="0.3 0 0.25" rpy="3.14159265358979 0 0" />
    <parent link="base_link" />
    <child link="laser" />
  </joint>
<link
    name="servo_link1_link">
    <inertial>
      <origin
        xyz="0 0 0"
        rpy="0 0 0" />
      <mass
        value="7.39299387464192" />
      <inertia
        ixx="0"
        ixy="0"
        ixz="0"
        iyy="0"
        iyz="0"
        izz="0" />
    </inertial>
    <visual>
      <origin
        xyz="0 0 0"
        rpy="0 0 0" />
      <geometry>
        <mesh
          filename="package://ir100_description/meshes/servo_link1.stl" />
      </geometry>
      <material
        name="">
        <color
          rgba="1 1 1 1" />
      </material>
    </visual>
    <collision>
      <origin
        xyz="0 0 0"
        rpy="0 0 0" />
      <geometry>
        <mesh
          filename="package://ir100_description/meshes/servo_link1.stl" />
      </geometry>
    </collision>
  </link>
  <joint
    name="servo_link1_joint"
    type="revolute">
    <origin
      xyz="0.08 0 0.13"
      rpy="0 0 0" />
    <parent
      link="hand_link" />
    <child
      link="servo_link1_link" />
    <axis
      xyz="0 0 1" />
    <limit
      lower="-2.35"
      upper="2.35"
      effort="0"
      velocity="1" />
  </joint>


<link
    name="servo_link2_link">
    <inertial>
      <origin
        xyz="0 0 0"
        rpy="0 0 0" />
      <mass
        value="7.39299387464192" />
      <inertia
        ixx="0"
        ixy="0"
        ixz="0"
        iyy="0"
        iyz="0"
        izz="0" />
    </inertial>
    <visual>
      <origin
        xyz="0 0 0"
        rpy="0 0 0" />
      <geometry>
        <mesh
          filename="package://ir100_description/meshes/servo_link2.stl" />
      </geometry>
      <material
        name="">
        <color
          rgba="1 1 1 1" />
      </material>
    </visual>
    <collision>
      <origin
        xyz="0 0 0"
        rpy="0 0 0" />
      <geometry>
        <mesh
          filename="package://ir100_description/meshes/servo_link2.stl" />
      </geometry>
    </collision>
  </link>
  <joint
    name="servo_link2_joint"
    type="revolute">
    <origin
      xyz="0.014 0 0.135"
      rpy="0 0 0" />
    <parent
      link="servo_link1_link" />
    <child
      link="servo_link2_link" />
    <axis
      xyz="0 1 0" />
    <limit
      lower="-1.48"
      upper="1.48"
      effort="0"
      velocity="1" />
  </joint>

</xacro:macro>


</robot>


